Traceback (most recent call last):
  File "myth_run.py", line 43, in parse
    output = subprocess.run(cmd,stdout = f,stderr = f,shell=True,check=True,timeout=3660,text=True)
  File "/home/amax/anaconda3/envs/python3.8/lib/python3.8/subprocess.py", line 495, in run
    stdout, stderr = process.communicate(input, timeout=timeout)
  File "/home/amax/anaconda3/envs/python3.8/lib/python3.8/subprocess.py", line 1028, in communicate
    stdout, stderr = self._communicate(input, endtime, timeout)
  File "/home/amax/anaconda3/envs/python3.8/lib/python3.8/subprocess.py", line 1894, in _communicate
    self.wait(timeout=self._remaining_time(endtime))
  File "/home/amax/anaconda3/envs/python3.8/lib/python3.8/subprocess.py", line 1083, in wait
    return self._wait(timeout=timeout)
  File "/home/amax/anaconda3/envs/python3.8/lib/python3.8/subprocess.py", line 1798, in _wait
    raise TimeoutExpired(self.args, timeout)
subprocess.TimeoutExpired: Command 'myth analyze /bdata2/sc/dataset/mainnet/0xD9822E155c36Fc4E8CB396444096FffE1560769C.sol --execution-timeout 3600 --solv 0.7.6 -t 3' timed out after 3659.9997152858414 seconds

