Traceback (most recent call last):
  File "test1.py", line 44, in parse
    output = subprocess.run(cmd,stdout = subprocess.PIPE,stderr = subprocess.PIPE,shell=True,check=False,timeout=3660,text=True)
  File "/home/amax/anaconda3/envs/python3.8/lib/python3.8/subprocess.py", line 495, in run
    stdout, stderr = process.communicate(input, timeout=timeout)
  File "/home/amax/anaconda3/envs/python3.8/lib/python3.8/subprocess.py", line 1028, in communicate
    stdout, stderr = self._communicate(input, endtime, timeout)
  File "/home/amax/anaconda3/envs/python3.8/lib/python3.8/subprocess.py", line 1869, in _communicate
    self._check_timeout(endtime, orig_timeout, stdout, stderr)
  File "/home/amax/anaconda3/envs/python3.8/lib/python3.8/subprocess.py", line 1072, in _check_timeout
    raise TimeoutExpired(
subprocess.TimeoutExpired: Command 'myth analyze /bdata2/sc/dataset/mainnet/0xd229922B9837F2d31EaBa05c1B9B95e976EEf3D4.sol --execution-timeout 3600 --solv 0.8.7 -t 3' timed out after 3660 seconds

