Traceback (most recent call last):
  File "test3.py", line 43, in parse
    output = subprocess.run(cmd,stdout = subprocess.PIPE,stderr = subprocess.PIPE,shell=True,check=False,timeout=7200,text=True)
  File "/home/amax/anaconda3/envs/python3.8/lib/python3.8/subprocess.py", line 495, in run
    stdout, stderr = process.communicate(input, timeout=timeout)
  File "/home/amax/anaconda3/envs/python3.8/lib/python3.8/subprocess.py", line 1028, in communicate
    stdout, stderr = self._communicate(input, endtime, timeout)
  File "/home/amax/anaconda3/envs/python3.8/lib/python3.8/subprocess.py", line 1869, in _communicate
    self._check_timeout(endtime, orig_timeout, stdout, stderr)
  File "/home/amax/anaconda3/envs/python3.8/lib/python3.8/subprocess.py", line 1072, in _check_timeout
    raise TimeoutExpired(
subprocess.TimeoutExpired: Command 'myth analyze /bdata2/sc/dataset/mainnet/0x72a8e0272fdf57f26588dfca90082f01d51cb29a.sol --execution-timeout 3600 --solv v0.4.24 -t 3' timed out after 7200 seconds

