mythril.interfaces.cli [ERROR]: Traceback (most recent call last):
  File "/home/amax/anaconda3/envs/python3.8/lib/python3.8/site-packages/mythril/interfaces/cli.py", line 967, in parse_args_and_execute
    address = load_code(disassembler, args)
  File "/home/amax/anaconda3/envs/python3.8/lib/python3.8/site-packages/mythril/interfaces/cli.py", line 719, in load_code
    address, _ = disassembler.load_from_solidity(
  File "/home/amax/anaconda3/envs/python3.8/lib/python3.8/site-packages/mythril/mythril/mythril_disassembler.py", line 255, in load_from_solidity
    self.sigs.import_solidity_file(
  File "/home/amax/anaconda3/envs/python3.8/lib/python3.8/site-packages/mythril/support/signatures.py", line 246, in import_solidity_file
    self.add_sigs(file_path, solc_json)
  File "/home/amax/anaconda3/envs/python3.8/lib/python3.8/site-packages/mythril/support/signatures.py", line 258, in add_sigs
    self.add(sig, name)
  File "/home/amax/anaconda3/envs/python3.8/lib/python3.8/site-packages/mythril/support/signatures.py", line 182, in add
    cur.execute(
sqlite3.OperationalError: database is locked

